WARNING:__main__:Неверный тип данных для объекта Runner
Traceback (most recent call last):
  File "/home/server/HumanMoveTest/tests_12_4.py", line 31, in test_run
    runner = Runner(False)
             ^^^^^^^^^^^^^
  File "/home/server/HumanMoveTest/rt_with_exceptions.py", line 6, in __init__
    raise TypeError(f'Имя может быть только строкой, передано {type(name).__name__}')
TypeError: Имя может быть только строкой, передано bool
WARNING:__main__:Неверная скорость для Runner
Traceback (most recent call last):
  File "/home/server/HumanMoveTest/tests_12_4.py", line 20, in test_walk
    runner = Runner("John", -2)
             ^^^^^^^^^^^^^^^^^^
  File "/home/server/HumanMoveTest/rt_with_exceptions.py", line 11, in __init__
    raise ValueError(f'Скорость не может быть отрицательной, сейчас {speed}')
ValueError: Скорость не может быть отрицательной, сейчас -2
